Workbook

Sheet Cover Page

Sheet Data Log
B2: Data Log
B4: # | C4: Variable | D4: Unit | E4: Value | F4: Source | G4: Frequency | H4: Geography | I4: Date | J4: Used In Model | K4: Note
B6: 1 | C6: Electricity Price Data
C8: Day-ahead market prices | D8: EUR/MWh | E8: — | F8: ENTSO-E Transparency Platform, 2025 | G8: Hourly | H8: DK1/DK2 | I8: 01/01/2019 - 31/12/2025 | J8: OU Calibration, Monte Carlo Simulation
B10: 2 | C10: Solar and Consumption Data - Capture Price Inputs
C12: Solar Power Production over 40 kW | D12: MWh | E12: — | F12: Energy Data Service (Energinet.dk), 2025 | G12: Hourly | H12: DK1/DK2 | I12: 01/01/2019 - 31/12/2025 | J12: Cannibalisation regression α(t)
C13: Power Gross Consumption MWh | D13: MWh | E13: — | F13: Energy Data Service (Energinet.dk), 2025 | G13: Hourly | H13: DK1/DK2 | I13: 01/01/2019 - 31/12/2025 | J13: Cannibalisation regression α(t)
B15: 3 | C15: Derived Cannibalisation Variables - Capture Price Inputs & Calibration
C17: Solar penetration proxy | D17: % | E17: Derived | F17: Energy Data Service (Energinet.dk), 2025 | G17: Monthly | H17: DK1/DK2 | I17: 01/01/2019 - 31/12/2025 | J17: Cannibalisation regression α(t): independent variable (X) for estimating α(t) | K17: Solar Penetration Proxy = Solar Production MWh / Gross Consumption MWh
C18: Capture Prices | D18: EUR/MWh | E18: Derived | F18: Energy Data Service (Energinet.dk), 2025 | G18: Monthly | H18: DK1/DK2 | I18: 01/01/2019 - 31/12/2025 | J18: Cannibalisation regression α(t): used to calculate CPR | K18: Σ(Price × Solar Production) / Σ(Solar Production)
C19: Capture Price Ratio (CPR) | D19: Ratio | E19: Derived | F19: Energy Data Service (Energinet.dk), 2025 | G19: Monthly | H19: DK1/DK2 | I19: 01/01/2019 - 31/12/2025 | J19: Cannibalisation regression α(t): dependent variable (Y) for estimating α(t) | K19: Capture Price / Spot Price
B21: 4 | C21: Financial Input - Assumptions & WACC
C23: Risk-free rate (Rf) | D23: % | E23: 0.0225 | F23: Danmarks Nationalbank, 2025 | G23: Point estimate | H23: Denmark | I23: 2026 | J23: PPA WACC, Merchant WACC | K23: 2.25% Danske Stat 2035
C24: Equity Risk Premium (ERP) | D24: % | E24: 0.0423 | F24: Damodaran: Country Risk Premiums (Denmark, Aaa), 2026 | G24: Annual | H24: Denmark | I24: 2026 | J24: PPA WACC, Merchant WACC
C26: β_PPA (unlevered) | D26: — | E26: 0.46 | F26: Damodaran: Power sector, Global Betas by Sector, 2026 | G26: Annual | H26: Global | I26: 2026 | J26: PPA WACC
C27: β_merchant (unlevered) | D27: — | E27: 0.57 | F27: Damodaran: Green & Renewable Energy, Global Betas, 2026 | G27: Annual | H27: Global | I27: 2026 | J27: Merchant WACC
C29: Debt margin (PPA phase) | D29: % spread | E29: 0.0175 | F29: Gatti, 2019; IRENA, The Cost of Financing for Renewable Power, 2023 | G29: Point estimate | H29: Europe | I29: 2023 | J29: r_d,PPA for WACC_PPA | K29: Debt margins represent midpoints of indicative ranges for European contracted (150-200 bps) and merchant-exposed (300-350 bps) renewable project finance, consistent with Gatti (2019) and IRENA (2023)
C30: Debt margin (Merchant phase) | D30: % spread | E30: 0.0325 | F30: Gatti, 2019; IRENA, The Cost of Financing for Renewable Power, 2023 | G30: Point estimate | H30: Europe | I30: 2023 | J30: r_d,merchant for WACC_merchant | K30: Debt margins represent midpoints of indicative ranges for European contracted (150-200 bps) and merchant-exposed (300-350 bps) renewable project finance, consistent with Gatti (2019) and IRENA (2023)
C32: Equity Share (PPA phase) | D32: % | E32: 0.25 | F32: Gatti, 2019; Steffen, 2020 | G32: Point estimate | H32: Europe | I32: 2020 | J32: WACC_PPA (equity weight) | K32: 25% equity PPA consistent with 70-80% debt standard for contracted renewables (Gatti, 2019); 45% equity merchant reflects reduced debt capacity under unhedged exposure (Steffen, 2020)
C33: Equity Share (Merchant phase) | D33: % | E33: 0.45 | F33: Gatti, 2019; Steffen, 2020 | G33: Point estimate | H33: Europe | I33: 2020 | J33: WACC_merchant (equity weight) | K33: 25% equity PPA consistent with 70-80% debt standard for contracted renewables (Gatti, 2019); 45% equity merchant reflects reduced debt capacity under unhedged exposure (Steffen, 2020)
C35: Corporate tax rate (τ) | D35: % | E35: 0.22 | F35: Damodaran Country Risk Premiums, 2026; Skattestyrelsen, 2025 | G35: Point estimate | H35: Denmark | I35: 2026 | J35: WACC, FCFF model
B37: 5 | C37: Technical and Commercial Input - Assumptions
C39: CAPEX | D39: USD/kW | E39: 500 | F39: IRENA, Renewable Power Generation Costs, 2024 | G39: Annual | H39: Europe | I39: 2024 | J39: FCFF model | K39: EUR/USD conversion at time of modelling required
C40: OPEX | D40: USD/kW/year | E40: 9 | F40: Wood Mackenzie, Europe LCOE Report, 2024 | G40: Annual | H40: Europe | I40: 2024 | J40: FCFF model
C41: OPEX Escalation | D41: % | E41: 0.02 | F41: European Central Bank, 2025 | I41: 2025 | J41: FCFF model | K41: European Central Bank, ECB inflation target 2%, consistent with Danish long-run inflation expectations
C43: PPA benchmark price | D43: EUR/MWh | E43: 45 | F43: Pexapark, 2025; LevelTen Energy Q3, 2025; KYOS, 2025; DK1 solar PPA reference price, March 2025 | G43: Point estimate | H43: DK1 | I43: 2025 | J43: Revenue model (PPA phase)
C44: Project capacity | D44: MW | E44: 50 | F44: IEA, 2025; Energinet, 2025 | G44: Point estimate | H44: Denmark | I44: 2025 | J44: Revenue model | K44: Representative Danish utility-scale
C45: Project life | D45: Years | E45: 25 | F45: IEA, 2025 | G45: Point estimate | H45: Denmark | I45: 2025 | J45: All models | K45: Standard for solar PV
C46: PPA duration | D46: Years | E46: 10 | F46: Pexapark, 2024 | G46: Point estimate | H46: Denmark | I46: 2024 | J46: Switch date T* | K46: Typical bankable PPA tenor in Denmark
C48: Panel degradation rate | D48: % p.a. | E48: 0.005 | F48: IEA Renewables 2025; IRENA industry standard | G48: Point estimate | H48: Global | I48: 2025 | J48: Production profile
C49: Capacity factor | D49: % | E49: 0.13 | F49: Derived: EurObserv'ER, 2024 | G49: Point estimate | H49: Denmark | I49: 2024 | J49: Revenue model | K49: 3,363 GWh production, 3,529 MW capacity, 8,760 hours
C50: Technical availability | D50: % | E50: 0.97 | F50: IEA, 2025; IRENA, 2024 | G50: Point estimate | H50: Global | I50: 2025 | J50: Production profile | K50: Industry standard for utility-scale solar PV (consistent with IEA/IRENA O&M benchmarks)
C51: Curtailment | D51: % | E51: 0.03 | F51: IEA Renewables, 2025 | G51: Point estimate | H51: Global | I51: 2025 | J51: Production profile | K51: Global solar PV curtailment rate 2024 per IEA Renewables 2025; applied as conservative Danish base case
C52: AC:DC Ratio | D52: Ratio | E52: 1 | F52: IEA, 2025; IRENA, 2024 | G52: Point estimate | H52: Global | I52: 2024 | J52: Production profile | K52: AC:DC ratio of 1.0 implies no DC oversizing — conservative baseline
C54: End

Sheet Assumptions
B2: Assumptions
B4: # | C4: Variable | D4: Unit | E4: Value | G4: Note
B6: 1 | C6: Timeline
C8: Start of Development | D8: Date | E8: 46023
C9: Start of Construction | D9: Date | E9: 47484
C10: Commercial Operation Date | D10: Date | E10: 48214
C11: Operational Lifetime | D11: Months | E11: ='Data Log'!E45*12 | G11: Input from Data Log
B13: 2 | C13: Technicalities
C15: Installed Capacity | D15: MW(dc) | E15: =+'Data Log'!E44 | G15: Input from Data Log
C16: Power Production
C18: NCF, P50 | D18: % | E18: ='Data Log'!E49*(1-Assumptions!E22)*(1-Assumptions!E23)*E25 | G18: Derived: NCF = Capacity Factor * (1 − Curtailment) * (1 − Degradation) * Technical Availability
C19: NCF, P90 | D19: % | G19: Will be calculated using Monte Carlo simulation
C20: NCF, P99 | D20: % | G20: Will be calculated using Monte Carlo simulation
C22: Curtailment | D22: % | E22: =+'Data Log'!E51 | G22: Input from Data Log
C23: Degradation | D23: % p.a. | E23: =+'Data Log'!E48 | G23: Input from Data Log
C24: AC:DC Ratio | D24: Ratio | E24: =+'Data Log'!E52 | G24: Input from Data Log
C25: Technical Availability | D25: % | E25: =+'Data Log'!E50 | G25: Input from Data Log
B27: 3 | C27: Project Costs
C29: Construction Costs
C31: CAPEX | D31: EURk | E31: ='Data Log'!E39*0.92*E15 | G31: Input from Data Log
C33: Operational Costs
C35: O&M | D35: EURk | E35: =+'Data Log'!E40*E15*0.92 | G35: Input from Data Log
C36: OPEX Escalation | D36: % p.a. | E36: =+'Data Log'!E41 | G36: Input from Data Log
B38: 4 | C38: Revenue
C40: PPA | D40: EUR/MWh | E40: =+'Data Log'!E43 | G40: Input from Data Log
C41: PPA Tenor | D41: Years | E41: =+'Data Log'!E46 | G41: Input from Data Log
C43: Merchant Price | D43: EUR/MWh | G43: Will be calculated using Monte Carlo simulation
B45: 5 | C45: Taxes
C47: Corporate Tax Rate | D47: % | E47: =+'Data Log'!E35
C49: End

Sheet WACC
B2: WACC
B4: # | C4: Parameter | D4: Unit | E4: Value | G4: Formula / Note
B6: 1 | C6: Macroeconomic Inputs
C8: Risk-free rate (Rf) | D8: % | E8: =+'Data Log'!E23 | G8: Input from Data Log
C9: Equity Risk Premium (ERP) | D9: % | E9: =+'Data Log'!E24 | G9: Input from Data Log
C10: Corporate tax rate (τ) | D10: % | E10: =+'Data Log'!E35 | G10: Input from Data Log
B12: 2 | C12: PPA Phase - Cost of Capital
C14: β_PPA (unlevered asset beta) | D14: — | E14: =+'Data Log'!E26 | G14: Input from Data Log
C15: Equity share — PPA (E/V) | D15: % | E15: =+'Data Log'!E32 | G15: Input from Data Log
C16: Debt share — PPA (D/V) | D16: % | E16: =1-E15 | G16: Derived: 1 - Equity Share - PPA (E/V)
C17: Debt margin — PPA | D17: % | E17: =+'Data Log'!E29 | G17: Input from Data Log
C18: r_e,PPA (cost of equity) | D18: % | E18: =E8+E14*E9 | G18: Derived: CAPM: Rf + β_PPA × ERP
C19: r_d,PPA (cost of debt) | D19: % | E19: =E8+E17 | G19: Derived: Rf + debt margin PPA
C20: WACC_PPA | D20: % | E20: =E15*E18+E16*E19*(1-E10) | G20: Derived: WACC_PPA = (E_PPA/V_PPA) · r_e,PPA + (D_PPA/V_PPA) · r_d,PPA · (1 − τ)
B22: 3 | C22: Merchant Phase - Cost of Capital
C24: β_merchant (unlevered asset beta) | D24: — | E24: =+'Data Log'!E27 | G24: Input from Data Log
C25: Equity share — Merchant (E/V) | D25: % | E25: =+'Data Log'!E33 | G25: Input from Data Log
C26: Debt share — Merchant (D/V) | D26: % | E26: =1-E25 | G26: Derived: 1 - Equity Share - Merchant (E/V)
C27: Debt margin — Merchant | D27: % | E27: =+'Data Log'!E30 | G27: Input from Data Log
C28: r_e,merchant (cost of equity) | D28: % | E28: =E8+E24*E9 | G28: Derived: CAPM: Rf + β_merchant × ERP
C29: r_d,merchant (cost of debt) | D29: % | E29: =E8+E27 | G29: Derived: Rf + debt margin merchant
C30: WACC_merchant | D30: % | E30: =E25*E28+E26*E29*(1-E10) | G30: Derived: WACC_merchant = (E_merchant/V_merchant) · r_e,merchant + (D_merchant/V_merchant) · r_d,merchant · (1 − τ)
B32: 4 | C32: Monthly Discount Rates
C34: WACC_PPA,m (monthly) | D34: % | E34: =(1+E20)^(1/12)-1 | G34: Derived (Converted for monthly cash flow model)
C35: WACC_merchant,m (monthly) | D35: % | E35: =(1+E30)^(1/12)-1 | G35: Derived (Converted for monthly cash flow model)
B37: 5 | C37: Beta Shift Summary
C39: Δβ (beta shift) | D39: — | E39: =E24-E14 | G39: β_merchant (unlevered asset beta) - β_PPA (unlevered asset beta)
C40: ΔWACC (discount rate shift) | D40: % | E40: =E30-E20 | G40: WACC_merchant - WACC_PPA
C42: Three-channel WACC differentiation: | G42: 1) r_e rises via beta shift
G43: 2) r_d rises via higher credit spread
G44: 3) D/V falls via reduced debt capacity
C46: End

Sheet Electricity Price Data
A1: Month | B1: DK1 Spot Price (EUR/MWh) — Primary | C1: DK2 Spot Price (EUR/MWh) — Robustness | D1: DK1 Seasonal Component (EUR/MWh) | E1: DK1 De-seasonalised Price (EUR/MWh) | F1: DK2 Seasonal Component (EUR/MWh) | G1: DK2 De-seasonalised Price (EUR/MWh)
A2: 2019-01 | B2: 50.295645 | C2: 51.655027 | D2: 75.530384 | E2: -25.234739 | F2: 74.231822 | G2: -22.576795
A3: 2019-02 | B3: 42.813958 | C3: 43.932946 | D3: 72.914187 | E3: -30.100228 | F3: 70.12802 | G3: -26.195074
A4: 2019-03 | B4: 33.608259 | C4: 35.667355 | D4: 82.507618 | E4: -48.899359 | F4: 80.579396 | G4: -44.912041
A5: 2019-04 | B5: 39.068417 | C5: 39.892097 | D5: 70.829002 | E5: -31.760585 | F5: 68.268173 | G5: -28.376075
A6: 2019-05 | B6: 37.429516 | C6: 38.151398 | D6: 68.052166 | E6: -30.62265 | F6: 66.059996 | G6: -27.908598
A7: 2019-06 | B7: 32.879222 | C7: 33.622236 | D7: 80.334095 | E7: -47.454873 | F7: 80.703994 | G7: -47.081758
A8: 2019-07 | B8: 38.817312 | C8: 39.000175 | D8: 89.731125 | E8: -50.913813 | F8: 83.978132 | G8: -44.977957
A9: 2019-08 | B9: 37.865699 | C9: 39.493172 | D9: 120.61983 | E9: -82.754126 | F9: 121.25327 | G9: -81.760094
A10: 2019-09 | B10: 35.378861 | C10: 37.321347 | D10: 110.13558 | E10: -74.756714 | F10: 109.81753 | G10: -72.496187
A11: 2019-10 | B11: 38.347402 | C11: 41.599354 | D11: 76.225889 | E11: -37.878486 | F11: 75.426141 | G11: -33.826787
A12: 2019-11 | B12: 41.745069 | C12: 42.696444 | D12: 89.133429 | E12: -47.38836 | F12: 90.04428 | G12: -47.347836
A13: 2019-12 | B13: 34.041976 | C13: 35.34711 | D13: 107.33221 | E13: -73.290233 | F13: 108.60634 | G13: -73.259228
... A85: 2025-12 | B85: 82.437466 | C85: 82.081529 | D85: 107.33221 | E85: -24.894743 | F85: 108.60634 | G85: -26.524809

Sheet Capture Price Inputs
A1: Month | B1: DK1 Solar Production (MWh) — Primary | C1: DK2 Solar Production (MWh) — Robustness | D1: DK1 Gross Consumption (MWh) | E1: DK2 Gross Consumption (MWh) | F1: DK1 Solar Penetration (%) — Primary | G1: DK2 Solar Penetration (%) — Robustness | H1: DK1 Capture Price (EUR/MWh) — Primary | I1: DK2 Capture Price (EUR/MWh) — Robustness | J1: DK1 CPR — Primary | K1: DK2 CPR — Robustness
A2: 2019-01 | B2: 0 | C2: 0 | D2: 1981398.6 | E2: 1314033.1
A3: 2019-02 | B3: 0 | C3: 0 | D3: 1722773.8 | E3: 1131046.6
A4: 2019-03 | B4: 0 | C4: 0 | D4: 1852201.6 | E4: 1198126.6
A5: 2019-04 | B5: 0 | C5: 0 | D5: 1635794.5 | E5: 1043346.8
A6: 2019-05 | B6: 0 | C6: 0 | D6: 1705809.8 | E6: 1053002.4
A7: 2019-06 | B7: 0 | C7: 0 | D7: 1584045.4 | E7: 975899.2
A8: 2019-07 | B8: 0 | C8: 0 | D8: 1586666.8 | E8: 974240.52
A9: 2019-08 | B9: 0 | C9: 0 | D9: 1656328 | E9: 1032294
A10: 2019-09 | B10: 0 | C10: 0 | D10: 1676866.1 | E10: 1027039.5
A11: 2019-10 | B11: 0 | C11: 0 | D11: 1811180.1 | E11: 1150263.6
A12: 2019-11 | B12: 0 | C12: 0 | D12: 1863227.8 | E12: 1178952.8
A13: 2019-12 | B13: 0 | C13: 0 | D13: 1899232.9 | E13: 1242107.4
A14: 2020-01 | B14: 4471 | C14: 2331 | D14: 1974432.7 | E14: 1250319.8 | F14: 0.0022644479 | G14: 0.001864323 | H14: 25.22321 | I14: 29.862136 | J14: 1.0091487 | K14: 1.0904463
A15: 2020-02 | B15: 10110 | C15: 5861 | D15: 1926649.3 | E15: 1181334.2 | F15: 0.005247452 | G15: 0.0049613393 | H15: 22.835819 | I15: 23.555518 | J15: 1.2985912 | K15: 1.2518213
A16: 2020-03 | B16: 38892 | C16: 18129 | D16: 1925186.6 | E16: 1183329.3 | F16: 0.020201678 | G16: 0.015320333 | H16: 15.941073 | I16: 17.149051 | J16: 0.87101469 | K16: 0.85520776
A17: 2020-04 | B17: 55159 | C17: 26915 | D17: 1700968.8 | E17: 1028051.5 | F17: 0.03242799 | G17: 0.026180595 | H17: 10.364876 | I17: 13.252523 | J17: 0.71315773 | K17: 0.76362024
A18: 2020-05 | B18: 61569 | C18: 33210 | D18: 1706453.7 | E18: 1030057.1 | F18: 0.036080087 | G18: 0.032240931 | H18: 15.478549 | I18: 18.594049 | J18: 0.96415577 | K18: 0.97636938
A19: 2020-06 | B19: 61474 | C19: 30998 | D19: 1643091.5 | E19: 1011294.2 | F19: 0.037413619 | G19: 0.030651812 | H19: 27.313308 | I19: 35.21078 | J19: 1.0394664 | K19: 1.180647
A20: 2020-07 | B20: 54854 | C20: 29317 | D20: 1613427.3 | E20: 977817.81 | F20: 0.033998434 | G20: 0.029982068 | H20: 24.831745 | I20: 26.450778 | J20: 1.0086182 | K20: 1.021791
A21: 2020-08 | B21: 59389 | C21: 28887 | D21: 1735264 | E21: 1030401.1 | F21: 0.034224763 | G21: 0.028034713 | H21: 33.876915 | I21: 44.113765 | J21: 0.98082264 | K21: 1.0779484
A22: 2020-09 | B22: 41721 | C22: 21825 | D22: 1714785.8 | E22: 1004072.5 | F22: 0.024330152 | G22: 0.021736479 | H22: 38.935979 | I22: 41.853048 | J22: 1.0104045 | K22: 1.0591891
A23: 2020-10 | B23: 21643 | C23: 12341 | D23: 1883574.4 | E23: 1113897.4 | F23: 0.011490388 | G23: 0.011079118 | H23: 31.927742 | I23: 33.600878 | J23: 1.2368022 | K23: 1.2475491
A24: 2020-11 | B24: 297 | C24: 128 | D24: 1952532.7 | E24: 1158936.2 | F24: 0.00015211013 | G24: 0.00011044612 | H24: 26.005993 | I24: 37.749766 | J24: 1.0947779 | K24: 1.0570804
A25: 2020-12 | B25: 31 | C25: 7 | D25: 2105390.9 | E25: 1242182.4 | F25: 1.4724107e-05 | G25: 5.6352434e-06 | H25: 34.795161 | I25: 44.191429 | J25: 1.0082302 | K25: 1.1256912
... A85: 2025-12 | B85: 32931.052 | C85: 13184.951 | D85: 2347966.7 | E85: 1453769.6 | F85: 0.014025349 | G85: 0.0090694912 | H85: 80.958034 | I85: 79.631228 | J85: 0.98205389 | K85: 0.97014796

Sheet Calibration
A1: ADF TEST RESULTS — DK1 PRIMARY | G1: Lags | H1: DK1 Full | I1: DK1 ex-2022 | J1: DK1 post-crisis | K1: CV 5%
A2: Sample | B2: Lags=0 | C2: Lags=1 | D2: Lags=2 | E2: Conclusion | G2: 0 | H2: -2.7049 | I2: -2.7732 | J2: -3.435 | K2: -2.89
A3: DK1 Full (2019-2025) | B3: -2.7049 | C3: -2.5651 | D3: -1.782 | E3: Weakly stationary | G3: 1 | H3: -2.5651 | I3: -2.3519 | J3: -3.4777 | K3: -2.89
A4: DK1 Full ex-2022 (primary) | B4: -2.7732 | C4: -2.3519 | D4: -1.8495 | E4: Stationary at 5% | G4: 2 | H4: -1.782 | I4: -1.8495 | J4: -2.6639 | K4: -2.89
A5: DK1 Post-crisis 2023-2025 | B5: -3.435 | C5: -3.4777 | D5: -2.6639 | E5: Stationary at 1% | G5: 3 | H5: -1.6911 | I5: -1.8987 | J5: -3.0968 | K5: -2.89
A6: DK2 Full ex-2022 (robustness) | B6: -3.1475 | C6: -2.5148 | D6: -1.8943 | E6: Robustness | G6: 4 | H6: -1.6501 | I6: -1.8872 | J6: -2.9904 | K6: -2.89
A7: Critical values: 1% = -3.51 | B7: 5% = -2.89 | C7: 10% = -2.58
A10: OU PARAMETER ESTIMATES
A11: Parameter | B11: DK1 ex-2022 (primary) | C11: DK1 post-crisis | D11: DK2 ex-2022 | E11: DK2 post-crisis
A12: Long-run mean (mu) EUR/MWh | B12: 68.2947 | C12: 77.6851 | D12: 67.3754 | E12: 77.2663
A13: Mean reversion (kappa) /month | B13: 0.1401 | C13: 0.5931 | D13: 0.1928 | E13: 0.7383
A14: Volatility (sigma) EUR/MWh | B14: 17.5069 | C14: 16.815 | D14: 19.3572 | E14: 18.0415
A15: Half-life (months) | B15: 4.95 | C15: 1.17 | D15: 3.59 | E15: 0.94
A16: Observations | B16: 72 | C16: 36 | D16: 72 | E16: 36
A19: SEASONAL COEFFICIENTS (OLS) — DK1 PRIMARY vs DK2 ROBUSTNESS
A20: Month | B20: DK1 Coefficient (EUR/MWh) | C20: DK2 Coefficient (EUR/MWh)
A21: Jan | B21: 75.53 | C21: 74.23
A22: Feb | B22: 72.91 | C22: 70.13
A23: Mar | B23: 82.51 | C23: 80.58
A24: Apr | B24: 70.83 | C24: 68.27
A25: May | B25: 68.05 | C25: 66.06
A26: Jun | B26: 80.33 | C26: 80.7
A27: Jul | B27: 89.73 | C27: 83.98
A28: Aug | B28: 120.62 | C28: 121.25
A29: Sep | B29: 110.14 | C29: 109.82
A30: Oct | B30: 76.23 | C30: 75.43
A31: Nov | B31: 89.13 | C31: 90.04
A32: Dec | B32: 107.33 | C32: 108.61
A35: CANNIBALISATION REGRESSION
A36: Parameter | B36: DK1 (primary) | C36: DK2 (robustness)
A37: Intercept (b0) | B37: 1.0513 | C37: 1.093
A38: Slope (b1) | B38: -2.0262 | C38: -4.3648
A39: R-squared | B39: 0.6658 | C39: 0.6409
A40: p-value (b1) | B40: 0 | C40: 0
A41: Sign check | B41: PASS | C41: PASS
A42: Observations | B42: 72 | C42: 72

Sheet Simulation
A1: Month | B1: Year | C1: mu_capture | D1: P50 | E1: P75 | F1: P90 | G1: P25 | H1: P10 | I1: P1 | K1: MC SIMULATION SUMMARY — DK1 PRIMARY
A2: 1 | B2: 0 | C2: 64.8799 | D2: 68.2947 | E2: 68.2947 | F2: 68.2947 | G2: 68.2947 | H2: 68.2947 | I2: 68.2947 | K2: Horizon | L2: P50 | M2: P90 | N2: P99 | O2: mu_capture
A3: 2 | B3: 0.0833 | C3: 64.8457 | D3: 67.8014 | E3: 78.8156 | F3: 88.792 | G3: 56.8474 | H3: 46.7156 | I3: 29.9044 | K3: Year 5 | L3: 62.42 | M3: 19.97 | N3: -14.85 | O3: 62.86
A4: 3 | B4: 0.1667 | C4: 64.8114 | D4: 67.716 | E4: 82.2192 | F4: 95.4219 | G4: 53.0994 | H4: 40.3735 | I4: 16.7822 | K4: Year 10 | L4: 60.67 | M4: 18.27 | N4: -17.66 | O4: 60.8
A5: 4 | B5: 0.25 | C5: 64.7771 | D5: 67.0428 | E5: 84.2939 | F5: 99.4051 | G5: 49.9277 | H5: 34.7439 | I5: 8.3993 | K5: Year 15 | L5: 58.52 | M5: 16.52 | N5: -15.45 | O5: 58.75
A6: 5 | B6: 0.3333 | C6: 64.7429 | D6: 66.6091 | E6: 85.5648 | F6: 101.8293 | G6: 48.1797 | H6: 31.6711 | I6: 1.8518 | K6: Year 20 | L6: 57.43 | M6: 14.71 | N6: -19.55 | O6: 56.69
A7: 6 | B7: 0.4167 | C7: 64.7086 | D7: 66.6004 | E7: 86.4228 | F7: 103.2061 | G7: 47.2189 | H7: 28.6783 | I7: -0.5872 | K7: Year 25 | L7: 54.79 | M7: 12.55 | N7: -22.5 | O7: 54.64
A8: 7 | B8: 0.5 | C8: 64.6744 | D8: 66.3599 | E8: 86.4675 | F8: 104.5352 | G8: 46.2468 | H8: 27.915 | I8: -3.1092
A9: 8 | B9: 0.5833 | C9: 64.6401 | D9: 66.1206 | E9: 86.9863 | F9: 105.3618 | G9: 45.8921 | H9: 26.7437 | I9: -3.7243 | K9: PARAMETERS USED (DK1 Primary)
A10: 9 | B10: 0.6667 | C10: 64.6058 | D10: 65.9305 | E10: 86.6401 | F10: 106.6822 | G10: 45.0162 | H10: 25.3956 | I10: -6.282 | K10: mu (EUR/MWh) | L10: 68.2947
A11: 10 | B11: 0.75 | C11: 64.5716 | D11: 65.7839 | E11: 87.5344 | F11: 106.2259 | G11: 44.5769 | H11: 24.3668 | I11: -7.1671 | K11: kappa (/month) | L11: 0.1401
A12: 11 | B12: 0.8333 | C12: 64.5373 | D12: 65.3835 | E12: 87.267 | F12: 106.8023 | G12: 43.8629 | H12: 25.1914 | I12: -9.9291 | K12: sigma (EUR/MWh) | L12: 17.5069
A13: 12 | B13: 0.9167 | C13: 64.503 | D13: 65.4964 | E13: 87.2853 | F13: 107.4839 | G13: 44.1724 | H13: 25.084 | I13: -10.277 | K13: N paths | L13: 10000
A14: 13 | B14: 1 | C14: 64.4688 | D14: 65.4259 | E14: 87.6909 | F14: 107.7007 | G14: 44.0839 | H14: 23.6892 | I14: -10.3538 | K14: Alpha(t=0) | L14: 5%
A15: 14 | B15: 1.0833 | C15: 64.4345 | D15: 65.3168 | E15: 87.2552 | F15: 107.1667 | G15: 43.4157 | H15: 23.858 | I15: -10.6224 | K15: Alpha(t=25) | L15: 20%
A16: 15 | B16: 1.1667 | C16: 64.4003 | D16: 65.3124 | E16: 87.5832 | F16: 106.9542 | G16: 43.4516 | H16: 23.8034 | I16: -11.7282
A17: 16 | B17: 1.25 | C17: 64.366 | D17: 65.4709 | E17: 86.9666 | F17: 107.1016 | G17: 43.0965 | H17: 23.6992 | I17: -10.7847
A18: 17 | B18: 1.3333 | C18: 64.3317 | D18: 65.0741 | E18: 87.4701 | F18: 106.7117 | G18: 43.264 | H18: 23.9804 | I18: -10.3581
A19: 18 | B19: 1.4167 | C19: 64.2975 | D19: 65.3845 | E19: 87.0495 | F19: 106.6975 | G19: 42.6962 | H19: 22.4691 | I19: -10.7838
A20: 19 | B20: 1.5 | C20: 64.2632 | D20: 65.3837 | E20: 87.492 | F20: 107.0715 | G20: 42.517 | H20: 22.1187 | I20: -10.436
A21: 20 | B21: 1.5833 | C21: 64.229 | D21: 64.921 | E21: 86.8609 | F21: 106.3661 | G21: 42.8854 | H21: 22.2167 | I21: -12.1113
A22: 21 | B22: 1.6667 | C22: 64.1947 | D22: 64.6719 | E22: 86.9376 | F22: 106.0552 | G22: 42.9933 | H22: 22.0319 | I22: -13.504
A23: 22 | B23: 1.75 | C23: 64.1604 | D23: 64.6659 | E23: 86.666 | F23: 106.5405 | G23: 42.2253 | H23: 22.427 | I23: -13.9411
A24: 23 | B24: 1.8333 | C24: 64.1262 | D24: 64.5806 | E24: 86.7883 | F24: 106.2385 | G24: 42.09 | H24: 21.8143 | I24: -13.6475
A25: 24 | B25: 1.9167 | C25: 64.0919 | D25: 64.753 | E25: 86.4153 | F25: 107.0212 | G25: 42.1765 | H25: 22.4859 | I25: -12.8962
A26: 25 | B26: 2 | C26: 64.0576 | D26: 64.5184 | E26: 86.7178 | F26: 106.5809 | G26: 42.3217 | H26: 21.6924 | I26: -12.7455
A27: 26 | B27: 2.0833 | C27: 64.0234 | D27: 63.9402 | E27: 86.4723 | F27: 106.9217 | G27: 41.9212 | H27: 21.8213 | I27: -14.4254
... A301: 300 | B301: 24.9167 | C301: 54.6357 | D301: 54.7877 | E301: 77.5664 | F301: 97.0165 | G301: 32.5956 | H301: 12.547 | I301: -22.496

Sheet FCFF Model
A1: FCFF Model — Monthly Cash Flow Waterfall | 50MW Danish Solar PV | DK1 Primary
A2: All formulas linked to Assumptions (E15/E16/E23/E31/E35/E36/E40/E47) and WACC (E34/E35) sheets. Merchant prices from Simulation sheet cols E/I/J rows 7-306. PPA months 1-120 | Merchant months 121-300.
C3: PPA | D3: PPA | E3: PPA | F3: PPA | G3: PPA | H3: PPA | I3: PPA | J3: PPA | K3: PPA | L3: PPA | M3: PPA | N3: PPA | O3: PPA | P3: PPA | Q3: PPA | R3: PPA | S3: PPA | T3: PPA | U3: PPA | V3: PPA | W3: PPA | X3: PPA | Y3: PPA | Z3: PPA | AA3: PPA | AB3: PPA | AC3: PPA | AD3: PPA | AE3: PPA | AF3: PPA | AG3: PPA | AH3: PPA | AI3: PPA | AJ3: PPA | AK3: PPA | AL3: PPA | AM3: PPA | AN3: PPA | AO3: PPA | AP3: PPA | AQ3: PPA | AR3: PPA | AS3: PPA | AT3: PPA | AU3: PPA | AV3: PPA | AW3: PPA | AX3: PPA | AY3: PPA | AZ3: PPA | BA3: PPA | BB3: PPA | BC3: PPA | BD3: PPA | BE3: PPA | BF3: PPA | BG3: PPA | BH3: PPA | BI3: PPA | BJ3: PPA | BK3: PPA | BL3: PPA | BM3: PPA | BN3: PPA | BO3: PPA | BP3: PPA | BQ3: PPA | BR3: PPA | BS3: PPA | BT3: PPA | BU3: PPA | BV3: PPA | BW3: PPA | BX3: PPA | BY3: PPA | BZ3: PPA | CA3: PPA | CB3: PPA | CC3: PPA | CD3: PPA | CE3: PPA | CF3: PPA | CG3: PPA | CH3: PPA | CI3: PPA | CJ3: PPA | CK3: PPA | CL3: PPA | CM3: PPA | CN3: PPA | CO3: PPA | CP3: PPA | CQ3: PPA | CR3: PPA | CS3: PPA | CT3: PPA | CU3: PPA | CV3: PPA | CW3: PPA | CX3: PPA | CY3: PPA | CZ3: PPA | DA3: PPA | DB3: PPA | DC3: PPA | DD3: PPA | DE3: PPA | DF3: PPA | DG3: PPA | DH3: PPA | DI3: PPA | DJ3: PPA | DK3: PPA | DL3: PPA | DM3: PPA | DN3: PPA | DO3: PPA | DP3: PPA | DQ3: PPA | DR3: PPA | DS3: Merchant | DT3: Merchant | DU3: Merchant | DV3: Merchant | DW3: Merchant | DX3: Merchant | DY3: Merchant | DZ3: Merchant | EA3: Merchant | EB3: Merchant | EC3: Merchant | ED3: Merchant | EE3: Merchant | EF3: Merchant | EG3: Merchant | EH3: Merchant | EI3: Merchant | EJ3: Merchant | EK3: Merchant | EL3: Merchant | EM3: Merchant | EN3: Merchant | EO3: Merchant | EP3: Merchant | EQ3: Merchant | ER3: Merchant | ES3: Merchant | ET3: Merchant | EU3: Merchant | EV3: Merchant | EW3: Merchant | EX3: Merchant | EY3: Merchant | EZ3: Merchant | FA3: Merchant | FB3: Merchant | FC3: Merchant | FD3: Merchant | FE3: Merchant | FF3: Merchant | FG3: Merchant | FH3: Merchant | FI3: Merchant | FJ3: Merchant | FK3: Merchant | FL3: Merchant | FM3: Merchant | FN3: Merchant | FO3: Merchant | FP3: Merchant | FQ3: Merchant | FR3: Merchant | FS3: Merchant | FT3: Merchant | FU3: Merchant | FV3: Merchant | FW3: Merchant | FX3: Merchant | FY3: Merchant | FZ3: Merchant | GA3: Merchant | GB3: Merchant | GC3: Merchant | GD3: Merchant | GE3: Merchant | GF3: Merchant | GG3: Merchant | GH3: Merchant | GI3: Merchant | GJ3: Merchant | GK3: Merchant | GL3: Merchant | GM3: Merchant | GN3: Merchant | GO3: Merchant | GP3: Merchant | GQ3: Merchant | GR3: Merchant | GS3: Merchant | GT3: Merchant | GU3: Merchant | GV3: Merchant | GW3: Merchant | GX3: Merchant | GY3: Merchant | GZ3: Merchant | HA3: Merchant | HB3: Merchant | HC3: Merchant | HD3: Merchant | HE3: Merchant | HF3: Merchant | HG3: Merchant | HH3: Merchant | HI3: Merchant | HJ3: Merchant | HK3: Merchant | HL3: Merchant | HM3: Merchant | HN3: Merchant | HO3: Merchant | HP3: Merchant | HQ3: Merchant | HR3: Merchant | HS3: Merchant | HT3: Merchant | HU3: Merchant | HV3: Merchant | HW3: Merchant | HX3: Merchant | HY3: Merchant | HZ3: Merchant | IA3: Merchant | IB3: Merchant | IC3: Merchant | ID3: Merchant | IE3: Merchant | IF3: Merchant | IG3: Merchant | IH3: Merchant | II3: Merchant | IJ3: Merchant | IK3: Merchant | IL3: Merchant | IM3: Merchant | IN3: Merchant | IO3: Merchant | IP3: Merchant | IQ3: Merchant | IR3: Merchant | IS3: Merchant | IT3: Merchant | IU3: Merchant | IV3: Merchant | IW3: Merchant | IX3: Merchant | IY3: Merchant | IZ3: Merchant | JA3: Merchant | JB3: Merchant | JC3: Merchant | JD3: Merchant | JE3: Merchant | JF3: Merchant | JG3: Merchant | JH3: Merchant | JI3: Merchant | JJ3: Merchant | JK3: Merchant | JL3: Merchant | JM3: Merchant | JN3: Merchant | JO3: Merchant | JP3: Merchant | JQ3: Merchant | JR3: Merchant | JS3: Merchant | JT3: Merchant | JU3: Merchant | JV3: Merchant | JW3: Merchant | JX3: Merchant | JY3: Merchant | JZ3: Merchant | KA3: Merchant | KB3: Merchant | KC3: Merchant | KD3: Merchant | KE3: Merchant | KF3: Merchant | KG3: Merchant | KH3: Merchant | KI3: Merchant | KJ3: Merchant | KK3: Merchant | KL3: Merchant | KM3: Merchant | KN3: Merchant | KO3: Merchant | KP3: Merchant
A4: Line Item | B4: Unit | C4: 1 | D4: 2 | E4: 3 | F4: 4 | G4: 5 | H4: 6 | I4: 7 | J4: 8 | K4: 9 | L4: 10 | M4: 11 | N4: 12 | O4: 13 | P4: 14 | Q4: 15 | R4: 16 | S4: 17 | T4: 18 | U4: 19 | V4: 20 | W4: 21 | X4: 22 | Y4: 23 | Z4: 24 | AA4: 25 | AB4: 26 | AC4: 27 | AD4: 28 | AE4: 29 | AF4: 30 | AG4: 31 | AH4: 32 | AI4: 33 | AJ4: 34 | AK4: 35 | AL4: 36 | AM4: 37 | AN4: 38 | AO4: 39 | AP4: 40 | AQ4: 41 | AR4: 42 | AS4: 43 | AT4: 44 | AU4: 45 | AV4: 46 | AW4: 47 | AX4: 48 | AY4: 49 | AZ4: 50 | BA4: 51 | BB4: 52 | BC4: 53 | BD4: 54 | BE4: 55 | BF4: 56 | BG4: 57 | BH4: 58 | BI4: 59 | BJ4: 60 | BK4: 61 | BL4: 62 | BM4: 63 | BN4: 64 | BO4: 65 | BP4: 66 | BQ4: 67 | BR4: 68 | BS4: 69 | BT4: 70 | BU4: 71 | BV4: 72 | BW4: 73 | BX4: 74 | BY4: 75 | BZ4: 76 | CA4: 77 | CB4: 78 | CC4: 79 | CD4: 80 | CE4: 81 | CF4: 82 | CG4: 83 | CH4: 84 | CI4: 85 | CJ4: 86 | CK4: 87 | CL4: 88 | CM4: 89 | CN4: 90 | CO4: 91 | CP4: 92 | CQ4: 93 | CR4: 94 | CS4: 95 | CT4: 96 | CU4: 97 | CV4: 98 | CW4: 99 | CX4: 100 | CY4: 101 | CZ4: 102 | DA4: 103 | DB4: 104 | DC4: 105 | DD4: 106 | DE4: 107 | DF4: 108 | DG4: 109 | DH4: 110 | DI4: 111 | DJ4: 112 | DK4: 113 | DL4: 114 | DM4: 115 | DN4: 116 | DO4: 117 | DP4: 118 | DQ4: 119 | DR4: 120 | DS4: 121 | DT4: 122 | DU4: 123 | DV4: 124 | DW4: 125 | DX4: 126 | DY4: 127 | DZ4: 128 | EA4: 129 | EB4: 130 | EC4: 131 | ED4: 132 | EE4: 133 | EF4: 134 | EG4: 135 | EH4: 136 | EI4: 137 | EJ4: 138 | EK4: 139 | EL4: 140 | EM4: 141 | EN4: 142 | EO4: 143 | EP4: 144 | EQ4: 145 | ER4: 146 | ES4: 147 | ET4: 148 | EU4: 149 | EV4: 150 | EW4: 151 | EX4: 152 | EY4: 153 | EZ4: 154 | FA4: 155 | FB4: 156 | FC4: 157 | FD4: 158 | FE4: 159 | FF4: 160 | FG4: 161 | FH4: 162 | FI4: 163 | FJ4: 164 | FK4: 165 | FL4: 166 | FM4: 167 | FN4: 168 | FO4: 169 | FP4: 170 | FQ4: 171 | FR4: 172 | FS4: 173 | FT4: 174 | FU4: 175 | FV4: 176 | FW4: 177 | FX4: 178 | FY4: 179 | FZ4: 180 | GA4: 181 | GB4: 182 | GC4: 183 | GD4: 184 | GE4: 185 | GF4: 186 | GG4: 187 | GH4: 188 | GI4: 189 | GJ4: 190 | GK4: 191 | GL4: 192 | GM4: 193 | GN4: 194 | GO4: 195 | GP4: 196 | GQ4: 197 | GR4: 198 | GS4: 199 | GT4: 200 | GU4: 201 | GV4: 202 | GW4: 203 | GX4: 204 | GY4: 205 | GZ4: 206 | HA4: 207 | HB4: 208 | HC4: 209 | HD4: 210 | HE4: 211 | HF4: 212 | HG4: 213 | HH4: 214 | HI4: 215 | HJ4: 216 | HK4: 217 | HL4: 218 | HM4: 219 | HN4: 220 | HO4: 221 | HP4: 222 | HQ4: 223 | HR4: 224 | HS4: 225 | HT4: 226 | HU4: 227 | HV4: 228 | HW4: 229 | HX4: 230 | HY4: 231 | HZ4: 232 | IA4: 233 | IB4: 234 | IC4: 235 | ID4: 236 | IE4: 237 | IF4: 238 | IG4: 239 | IH4: 240 | II4: 241 | IJ4: 242 | IK4: 243 | IL4: 244 | IM4: 245 | IN4: 246 | IO4: 247 | IP4: 248 | IQ4: 249 | IR4: 250 | IS4: 251 | IT4: 252 | IU4: 253 | IV4: 254 | IW4: 255 | IX4: 256 | IY4: 257 | IZ4: 258 | JA4: 259 | JB4: 260 | JC4: 261 | JD4: 262 | JE4: 263 | JF4: 264 | JG4: 265 | JH4: 266 | JI4: 267 | JJ4: 268 | JK4: 269 | JL4: 270 | JM4: 271 | JN4: 272 | JO4: 273 | JP4: 274 | JQ4: 275 | JR4: 276 | JS4: 277 | JT4: 278 | JU4: 279 | JV4: 280 | JW4: 281 | JX4: 282 | JY4: 283 | JZ4: 284 | KA4: 285 | KB4: 286 | KC4: 287 | KD4: 288 | KE4: 289 | KF4: 290 | KG4: 291 | KH4: 292 | KI4: 293 | KJ4: 294 | KK4: 295 | KL4: 296 | KM4: 297 | KN4: 298 | KO4: 299 | KP4: 300
A5: P50 — Base Case
A6: Production (MWh) | B6: MWh | C6: =Assumptions!$E$16*(1-Assumptions!$E$23)^0 | D6: =Assumptions!$E$16*(1-Assumptions!$E$23)^0 | E6: =Assumptions!$E$16*(1-Assumptions!$E$23)^0 | F6: =Assumptions!$E$16*(1-Assumptions!$E$23)^0 | G6: =Assumptions!$E$16*(1-Assumptions!$E$23)^0 | H6: =Assumptions!$E$16*(1-Assumptions!$E$23)^0 | I6: =Assumptions!$E$16*(1-Assumptions!$E$23)^0 | J6: =Assumptions!$E$16*(1-Assumptions!$E$23)^0 | ... N6: =Assumptions!$E$16*(1-Assumptions!$E$23)^0 | O6: =Assumptions!$E$16*(1-Assumptions!$E$23)^1 | P6: =Assumptions!$E$16*(1-Assumptions!$E$23)^1 | Q6: =Assumptions!$E$16*(1-Assumptions!$E$23)^1 | R6: =Assumptions!$E$16*(1-Assumptions!$E$23)^1 | S6: =Assumptions!$E$16*(1-Assumptions!$E$23)^1 | T6: =Assumptions!$E$16*(1-Assumptions!$E$23)^1 | U6: =Assumptions!$E$16*(1-Assumptions!$E$23)^1 | V6: =Assumptions!$E$16*(1-Assumptions!$E$23)^1 | ... Z6: =Assumptions!$E$16*(1-Assumptions!$E$23)^1 | AA6: =Assumptions!$E$16*(1-Assumptions!$E$23)^2 | AB6: =Assumptions!$E$16*(1-Assumptions!$E$23)^2 | AC6: =Assumptions!$E$16*(1-Assumptions!$E$23)^2 | AD6: =Assumptions!$E$16*(1-Assumptions!$E$23)^2 | AE6: =Assumptions!$E$16*(1-Assumptions!$E$23)^2 | AF6: =Assumptions!$E$16*(1-Assumptions!$E$23)^2 | AG6: =Assumptions!$E$16*(1-Assumptions!$E$23)^2 | AH6: =Assumptions!$E$16*(1-Assumptions!$E$23)^2 | ... AL6: =Assumptions!$E$16*(1-Assumptions!$E$23)^2 | AM6: =Assumptions!$E$16*(1-Assumptions!$E$23)^3 | AN6: =Assumptions!$E$16*(1-Assumptions!$E$23)^3 | AO6: =Assumptions!$E$16*(1-Assumptions!$E$23)^3 | AP6: =Assumptions!$E$16*(1-Assumptions!$E$23)^3 | AQ6: =Assumptions!$E$16*(1-Assumptions!$E$23)^3 | AR6: =Assumptions!$E$16*(1-Assumptions!$E$23)^3 | AS6: =Assumptions!$E$16*(1-Assumptions!$E$23)^3 | AT6: =Assumptions!$E$16*(1-Assumptions!$E$23)^3 | ... AX6: =Assumptions!$E$16*(1-Assumptions!$E$23)^3 | AY6: =Assumptions!$E$16*(1-Assumptions!$E$23)^4 | AZ6: =Assumptions!$E$16*(1-Assumptions!$E$23)^4 | BA6: =Assumptions!$E$16*(1-Assumptions!$E$23)^4 | BB6: =Assumptions!$E$16*(1-Assumptions!$E$23)^4 | BC6: =Assumptions!$E$16*(1-Assumptions!$E$23)^4 | BD6: =Assumptions!$E$16*(1-Assumptions!$E$23)^4 | BE6: =Assumptions!$E$16*(1-Assumptions!$E$23)^4 | BF6: =Assumptions!$E$16*(1-Assumptions!$E$23)^4 | ... BJ6: =Assumptions!$E$16*(1-Assumptions!$E$23)^4 | BK6: =Assumptions!$E$16*(1-Assumptions!$E$23)^5 | BL6: =Assumptions!$E$16*(1-Assumptions!$E$23)^5 | BM6: =Assumptions!$E$16*(1-Assumptions!$E$23)^5 | BN6: =Assumptions!$E$16*(1-Assumptions!$E$23)^5 | BO6: =Assumptions!$E$16*(1-Assumptions!$E$23)^5 | BP6: =Assumptions!$E$16*(1-Assumptions!$E$23)^5 | BQ6: =Assumptions!$E$16*(1-Assumptions!$E$23)^5 | BR6: =Assumptions!$E$16*(1-Assumptions!$E$23)^5 | ... BV6: =Assumptions!$E$16*(1-Assumptions!$E$23)^5 | BW6: =Assumptions!$E$16*(1-Assumptions!$E$23)^6 | BX6: =Assumptions!$E$16*(1-Assumptions!$E$23)^6 | BY6: =Assumptions!$E$16*(1-Assumptions!$E$23)^6 | BZ6: =Assumptions!$E$16*(1-Assumptions!$E$23)^6 | CA6: =Assumptions!$E$16*(1-Assumptions!$E$23)^6 | CB6: =Assumptions!$E$16*(1-Assumptions!$E$23)^6 | CC6: =Assumptions!$E$16*(1-Assumptions!$E$23)^6 | CD6: =Assumptions!$E$16*(1-Assumptions!$E$23)^6 | ... CH6: =Assumptions!$E$16*(1-Assumptions!$E$23)^6 | CI6: =Assumptions!$E$16*(1-Assumptions!$E$23)^7 | CJ6: =Assumptions!$E$16*(1-Assumptions!$E$23)^7 | CK6: =Assumptions!$E$16*(1-Assumptions!$E$23)^7 | CL6: =Assumptions!$E$16*(1-Assumptions!$E$23)^7 | CM6: =Assumptions!$E$16*(1-Assumptions!$E$23)^7 | CN6: =Assumptions!$E$16*(1-Assumptions!$E$23)^7 | CO6: =Assumptions!$E$16*(1-Assumptions!$E$23)^7 | CP6: =Assumptions!$E$16*(1-Assumptions!$E$23)^7 | ... CT6: =Assumptions!$E$16*(1-Assumptions!$E$23)^7 | CU6: =Assumptions!$E$16*(1-Assumptions!$E$23)^8 | CV6: =Assumptions!$E$16*(1-Assumptions!$E$23)^8 | CW6: =Assumptions!$E$16*(1-Assumptions!$E$23)^8 | CX6: =Assumptions!$E$16*(1-Assumptions!$E$23)^8 | CY6: =Assumptions!$E$16*(1-Assumptions!$E$23)^8 | CZ6: =Assumptions!$E$16*(1-Assumptions!$E$23)^8 | DA6: =Assumptions!$E$16*(1-Assumptions!$E$23)^8 | DB6: =Assumptions!$E$16*(1-Assumptions!$E$23)^8 | ... DF6: =Assumptions!$E$16*(1-Assumptions!$E$23)^8 | DG6: =Assumptions!$E$16*(1-Assumptions!$E$23)^9 | DH6: =Assumptions!$E$16*(1-Assumptions!$E$23)^9 | DI6: =Assumptions!$E$16*(1-Assumptions!$E$23)^9 | DJ6: =Assumptions!$E$16*(1-Assumptions!$E$23)^9 | DK6: =Assumptions!$E$16*(1-Assumptions!$E$23)^9 | DL6: =Assumptions!$E$16*(1-Assumptions!$E$23)^9 | DM6: =Assumptions!$E$16*(1-Assumptions!$E$23)^9 | DN6: =Assumptions!$E$16*(1-Assumptions!$E$23)^9 | ... DR6: =Assumptions!$E$16*(1-Assumptions!$E$23)^9 | DS6: =Assumptions!$E$16*(1-Assumptions!$E$23)^10 | DT6: =Assumptions!$E$16*(1-Assumptions!$E$23)^10 | DU6: =Assumptions!$E$16*(1-Assumptions!$E$23)^10 | DV6: =Assumptions!$E$16*(1-Assumptions!$E$23)^10 | DW6: =Assumptions!$E$16*(1-Assumptions!$E$23)^10 | DX6: =Assumptions!$E$16*(1-Assumptions!$E$23)^10 | DY6: =Assumptions!$E$16*(1-Assumptions!$E$23)^10 | DZ6: =Assumptions!$E$16*(1-Assumptions!$E$23)^10 | ... ED6: =Assumptions!$E$16*(1-Assumptions!$E$23)^10 | EE6: =Assumptions!$E$16*(1-Assumptions!$E$23)^11 | EF6: =Assumptions!$E$16*(1-Assumptions!$E$23)^11 | EG6: =Assumptions!$E$16*(1-Assumptions!$E$23)^11 | EH6: =Assumptions!$E$16*(1-Assumptions!$E$23)^11 | EI6: =Assumptions!$E$16*(1-Assumptions!$E$23)^11 | EJ6: =Assumptions!$E$16*(1-Assumptions!$E$23)^11 | EK6: =Assumptions!$E$16*(1-Assumptions!$E$23)^11 | EL6: =Assumptions!$E$16*(1-Assumptions!$E$23)^11 | ... EP6: =Assumptions!$E$16*(1-Assumptions!$E$23)^11 | EQ6: =Assumptions!$E$16*(1-Assumptions!$E$23)^12 | ER6: =Assumptions!$E$16*(1-Assumptions!$E$23)^12 | ES6: =Assumptions!$E$16*(1-Assumptions!$E$23)^12 | ET6: =Assumptions!$E$16*(1-Assumptions!$E$23)^12 | EU6: =Assumptions!$E$16*(1-Assumptions!$E$23)^12 | EV6: =Assumptions!$E$16*(1-Assumptions!$E$23)^12 | EW6: =Assumptions!$E$16*(1-Assumptions!$E$23)^12 | EX6: =Assumptions!$E$16*(1-Assumptions!$E$23)^12 | ... FB6: =Assumptions!$E$16*(1-Assumptions!$E$23)^12 | FC6: =Assumptions!$E$16*(1-Assumptions!$E$23)^13 | FD6: =Assumptions!$E$16*(1-Assumptions!$E$23)^13 | FE6: =Assumptions!$E$16*(1-Assumptions!$E$23)^13 | FF6: =Assumptions!$E$16*(1-Assumptions!$E$23)^13 | FG6: =Assumptions!$E$16*(1-Assumptions!$E$23)^13 | FH6: =Assumptions!$E$16*(1-Assumptions!$E$23)^13 | FI6: =Assumptions!$E$16*(1-Assumptions!$E$23)^13 | FJ6: =Assumptions!$E$16*(1-Assumptions!$E$23)^13 | ... FN6: =Assumptions!$E$16*(1-Assumptions!$E$23)^13 | FO6: =Assumptions!$E$16*(1-Assumptions!$E$23)^14 | FP6: =Assumptions!$E$16*(1-Assumptions!$E$23)^14 | FQ6: =Assumptions!$E$16*(1-Assumptions!$E$23)^14 | FR6: =Assumptions!$E$16*(1-Assumptions!$E$23)^14 | FS6: =Assumptions!$E$16*(1-Assumptions!$E$23)^14 | FT6: =Assumptions!$E$16*(1-Assumptions!$E$23)^14 | FU6: =Assumptions!$E$16*(1-Assumptions!$E$23)^14 | FV6: =Assumptions!$E$16*(1-Assumptions!$E$23)^14 | ... FZ6: =Assumptions!$E$16*(1-Assumptions!$E$23)^14 | GA6: =Assumptions!$E$16*(1-Assumptions!$E$23)^15 | GB6: =Assumptions!$E$16*(1-Assumptions!$E$23)^15 | GC6: =Assumptions!$E$16*(1-Assumptions!$E$23)^15 | GD6: =Assumptions!$E$16*(1-Assumptions!$E$23)^15 | GE6: =Assumptions!$E$16*(1-Assumptions!$E$23)^15 | GF6: =Assumptions!$E$16*(1-Assumptions!$E$23)^15 | GG6: =Assumptions!$E$16*(1-Assumptions!$E$23)^15 | GH6: =Assumptions!$E$16*(1-Assumptions!$E$23)^15 | ... GL6: =Assumptions!$E$16*(1-Assumptions!$E$23)^15 | GM6: =Assumptions!$E$16*(1-Assumptions!$E$23)^16 | GN6: =Assumptions!$E$16*(1-Assumptions!$E$23)^16 | GO6: =Assumptions!$E$16*(1-Assumptions!$E$23)^16 | GP6: =Assumptions!$E$16*(1-Assumptions!$E$23)^16 | GQ6: =Assumptions!$E$16*(1-Assumptions!$E$23)^16 | GR6: =Assumptions!$E$16*(1-Assumptions!$E$23)^16 | GS6: =Assumptions!$E$16*(1-Assumptions!$E$23)^16 | GT6: =Assumptions!$E$16*(1-Assumptions!$E$23)^16 | ... GX6: =Assumptions!$E$16*(1-Assumptions!$E$23)^16 | GY6: =Assumptions!$E$16*(1-Assumptions!$E$23)^17 | GZ6: =Assumptions!$E$16*(1-Assumptions!$E$23)^17 | HA6: =Assumptions!$E$16*(1-Assumptions!$E$23)^17 | HB6: =Assumptions!$E$16*(1-Assumptions!$E$23)^17 | HC6: =Assumptions!$E$16*(1-Assumptions!$E$23)^17 | HD6: =Assumptions!$E$16*(1-Assumptions!$E$23)^17 | HE6: =Assumptions!$E$16*(1-Assumptions!$E$23)^17 | HF6: =Assumptions!$E$16*(1-Assumptions!$E$23)^17 | ... HJ6: =Assumptions!$E$16*(1-Assumptions!$E$23)^17 | HK6: =Assumptions!$E$16*(1-Assumptions!$E$23)^18 | HL6: =Assumptions!$E$16*(1-Assumptions!$E$23)^18 | HM6: =Assumptions!$E$16*(1-Assumptions!$E$23)^18 | HN6: =Assumptions!$E$16*(1-Assumptions!$E$23)^18 | HO6: =Assumptions!$E$16*(1-Assumptions!$E$23)^18 | HP6: =Assumptions!$E$16*(1-Assumptions!$E$23)^18 | HQ6: =Assumptions!$E$16*(1-Assumptions!$E$23)^18 | HR6: =Assumptions!$E$16*(1-Assumptions!$E$23)^18 | ... HV6: =Assumptions!$E$16*(1-Assumptions!$E$23)^18 | HW6: =Assumptions!$E$16*(1-Assumptions!$E$23)^19 | HX6: =Assumptions!$E$16*(1-Assumptions!$E$23)^19 | HY6: =Assumptions!$E$16*(1-Assumptions!$E$23)^19 | HZ6: =Assumptions!$E$16*(1-Assumptions!$E$23)^19 | IA6: =Assumptions!$E$16*(1-Assumptions!$E$23)^19 | IB6: =Assumptions!$E$16*(1-Assumptions!$E$23)^19 | IC6: =Assumptions!$E$16*(1-Assumptions!$E$23)^19 | ID6: =Assumptions!$E$16*(1-Assumptions!$E$23)^19 | ... IH6: =Assumptions!$E$16*(1-Assumptions!$E$23)^19 | II6: =Assumptions!$E$16*(1-Assumptions!$E$23)^20 | IJ6: =Assumptions!$E$16*(1-Assumptions!$E$23)^20 | IK6: =Assumptions!$E$16*(1-Assumptions!$E$23)^20 | IL6: =Assumptions!$E$16*(1-Assumptions!$E$23)^20 | IM6: =Assumptions!$E$16*(1-Assumptions!$E$23)^20 | IN6: =Assumptions!$E$16*(1-Assumptions!$E$23)^20 | IO6: =Assumptions!$E$16*(1-Assumptions!$E$23)^20 | IP6: =Assumptions!$E$16*(1-Assumptions!$E$23)^20 | ... IT6: =Assumptions!$E$16*(1-Assumptions!$E$23)^20 | IU6: =Assumptions!$E$16*(1-Assumptions!$E$23)^21 | IV6: =Assumptions!$E$16*(1-Assumptions!$E$23)^21 | IW6: =Assumptions!$E$16*(1-Assumptions!$E$23)^21 | IX6: =Assumptions!$E$16*(1-Assumptions!$E$23)^21 | IY6: =Assumptions!$E$16*(1-Assumptions!$E$23)^21 | IZ6: =Assumptions!$E$16*(1-Assumptions!$E$23)^21 | JA6: =Assumptions!$E$16*(1-Assumptions!$E$23)^21 | JB6: =Assumptions!$E$16*(1-Assumptions!$E$23)^21 | ... JF6: =Assumptions!$E$16*(1-Assumptions!$E$23)^21 | JG6: =Assumptions!$E$16*(1-Assumptions!$E$23)^22 | JH6: =Assumptions!$E$16*(1-Assumptions!$E$23)^22 | JI6: =Assumptions!$E$16*(1-Assumptions!$E$23)^22 | JJ6: =Assumptions!$E$16*(1-Assumptions!$E$23)^22 | JK6: =Assumptions!$E$16*(1-Assumptions!$E$23)^22 | JL6: =Assumptions!$E$16*(1-Assumptions!$E$23)^22 | JM6: =Assumptions!$E$16*(1-Assumptions!$E$23)^22 | JN6: =Assumptions!$E$16*(1-Assumptions!$E$23)^22 | ... JR6: =Assumptions!$E$16*(1-Assumptions!$E$23)^22 | JS6: =Assumptions!$E$16*(1-Assumptions!$E$23)^23 | JT6: =Assumptions!$E$16*(1-Assumptions!$E$23)^23 | JU6: =Assumptions!$E$16*(1-Assumptions!$E$23)^23 | JV6: =Assumptions!$E$16*(1-Assumptions!$E$23)^23 | JW6: =Assumptions!$E$16*(1-Assumptions!$E$23)^23 | JX6: =Assumptions!$E$16*(1-Assumptions!$E$23)^23 | JY6: =Assumptions!$E$16*(1-Assumptions!$E$23)^23 | JZ6: =Assumptions!$E$16*(1-Assumptions!$E$23)^23 | ... KD6: =Assumptions!$E$16*(1-Assumptions!$E$23)^23 | KE6: =Assumptions!$E$16*(1-Assumptions!$E$23)^24 | KF6: =Assumptions!$E$16*(1-Assumptions!$E$23)^24 | KG6: =Assumptions!$E$16*(1-Assumptions!$E$23)^24 | KH6: =Assumptions!$E$16*(1-Assumptions!$E$23)^24 | KI6: =Assumptions!$E$16*(1-Assumptions!$E$23)^24 | KJ6: =Assumptions!$E$16*(1-Assumptions!$E$23)^24 | KK6: =Assumptions!$E$16*(1-Assumptions!$E$23)^24 | KL6: =Assumptions!$E$16*(1-Assumptions!$E$23)^24 | ... KP6: =Assumptions!$E$16*(1-Assumptions!$E$23)^24
A7: Price (EUR/MWh) | B7: EUR/MWh | C7: =Assumptions!$E$40 | D7: =Assumptions!$E$40 | E7: =Assumptions!$E$40 | F7: =Assumptions!$E$40 | G7: =Assumptions!$E$40 | H7: =Assumptions!$E$40 | I7: =Assumptions!$E$40 | J7: =Assumptions!$E$40 | ... DR7: =Assumptions!$E$40 | DS7: =Simulation!$E$127 | DT7: =Simulation!$E$128 | DU7: =Simulation!$E$129 | DV7: =Simulation!$E$130 | DW7: =Simulation!$E$131 | DX7: =Simulation!$E$132 | DY7: =Simulation!$E$133 | DZ7: =Simulation!$E$134 | EA7: =Simulation!$E$135 | EB7: =Simulation!$E$136 | EC7: =Simulation!$E$137 | ED7: =Simulation!$E$138 | EE7: =Simulation!$E$139 | EF7: =Simulation!$E$140 | EG7: =Simulation!$E$141 | EH7: =Simulation!$E$142 | EI7: =Simulation!$E$143 | EJ7: =Simulation!$E$144 | EK7: =Simulation!$E$145 | EL7: =Simulation!$E$146 | EM7: =Simulation!$E$147 | EN7: =Simulation!$E$148 | EO7: =Simulation!$E$149 | EP7: =Simulation!$E$150 | EQ7: =Simulation!$E$151 | ER7: =Simulation!$E$152 | ES7: =Simulation!$E$153 | ET7: =Simulation!$E$154 | EU7: =Simulation!$E$155 | EV7: =Simulation!$E$156 | EW7: =Simulation!$E$157 | EX7: =Simulation!$E$158 | EY7: =Simulation!$E$159 | EZ7: =Simulation!$E$160 | FA7: =Simulation!$E$161 | FB7: =Simulation!$E$162 | FC7: =Simulation!$E$163 | FD7: =Simulation!$E$164 | FE7: =Simulation!$E$165 | FF7: =Simulation!$E$166 | FG7: =Simulation!$E$167 | FH7: =Simulation!$E$168 | FI7: =Simulation!$E$169 | FJ7: =Simulation!$E$170 | FK7: =Simulation!$E$171 | FL7: =Simulation!$E$172 | FM7: =Simulation!$E$173 | FN7: =Simulation!$E$174 | FO7: =Simulation!$E$175 | FP7: =Simulation!$E$176 | FQ7: =Simulation!$E$177 | FR7: =Simulation!$E$178 | FS7: =Simulation!$E$179 | FT7: =Simulation!$E$180 | FU7: =Simulation!$E$181 | FV7: =Simulation!$E$182 | FW7: =Simulation!$E$183 | FX7: =Simulation!$E$184 | FY7: =Simulation!$E$185 | FZ7: =Simulation!$E$186 | GA7: =Simulation!$E$187 | GB7: =Simulation!$E$188 | GC7: =Simulation!$E$189 | GD7: =Simulation!$E$190 | GE7: =Simulation!$E$191 | GF7: =Simulation!$E$192 | GG7: =Simulation!$E$193 | GH7: =Simulation!$E$194 | GI7: =Simulation!$E$195 | GJ7: =Simulation!$E$196 | GK7: =Simulation!$E$197 | GL7: =Simulation!$E$198 | GM7: =Simulation!$E$199 | GN7: =Simulation!$E$200 | GO7: =Simulation!$E$201 | GP7: =Simulation!$E$202 | GQ7: =Simulation!$E$203 | GR7: =Simulation!$E$204 | GS7: =Simulation!$E$205 | GT7: =Simulation!$E$206 | GU7: =Simulation!$E$207 | GV7: =Simulation!$E$208 | GW7: =Simulation!$E$209 | GX7: =Simulation!$E$210 | GY7: =Simulation!$E$211 | GZ7: =Simulation!$E$212 | HA7: =Simulation!$E$213 | HB7: =Simulation!$E$214 | HC7: =Simulation!$E$215 | HD7: =Simulation!$E$216 | HE7: =Simulation!$E$217 | HF7: =Simulation!$E$218 | HG7: =Simulation!$E$219 | HH7: =Simulation!$E$220 | HI7: =Simulation!$E$221 | HJ7: =Simulation!$E$222 | HK7: =Simulation!$E$223 | HL7: =Simulation!$E$224 | HM7: =Simulation!$E$225 | HN7: =Simulation!$E$226 | HO7: =Simulation!$E$227 | HP7: =Simulation!$E$228 | HQ7: =Simulation!$E$229 | HR7: =Simulation!$E$230 | HS7: =Simulation!$E$231 | HT7: =Simulation!$E$232 | HU7: =Simulation!$E$233 | HV7: =Simulation!$E$234 | HW7: =Simulation!$E$235 | HX7: =Simulation!$E$236 | HY7: =Simulation!$E$237 | HZ7: =Simulation!$E$238 | IA7: =Simulation!$E$239 | IB7: =Simulation!$E$240 | IC7: =Simulation!$E$241 | ID7: =Simulation!$E$242 | IE7: =Simulation!$E$243 | IF7: =Simulation!$E$244 | IG7: =Simulation!$E$245 | IH7: =Simulation!$E$246 | II7: =Simulation!$E$247 | IJ7: =Simulation!$E$248 | IK7: =Simulation!$E$249 | IL7: =Simulation!$E$250 | IM7: =Simulation!$E$251 | IN7: =Simulation!$E$252 | IO7: =Simulation!$E$253 | IP7: =Simulation!$E$254 | IQ7: =Simulation!$E$255 | IR7: =Simulation!$E$256 | IS7: =Simulation!$E$257 | IT7: =Simulation!$E$258 | IU7: =Simulation!$E$259 | IV7: =Simulation!$E$260 | IW7: =Simulation!$E$261 | IX7: =Simulation!$E$262 | IY7: =Simulation!$E$263 | IZ7: =Simulation!$E$264 | JA7: =Simulation!$E$265 | JB7: =Simulation!$E$266 | JC7: =Simulation!$E$267 | JD7: =Simulation!$E$268 | JE7: =Simulation!$E$269 | JF7: =Simulation!$E$270 | JG7: =Simulation!$E$271 | JH7: =Simulation!$E$272 | JI7: =Simulation!$E$273 | JJ7: =Simulation!$E$274 | JK7: =Simulation!$E$275 | JL7: =Simulation!$E$276 | JM7: =Simulation!$E$277 | JN7: =Simulation!$E$278 | JO7: =Simulation!$E$279 | JP7: =Simulation!$E$280 | JQ7: =Simulation!$E$281 | JR7: =Simulation!$E$282 | JS7: =Simulation!$E$283 | JT7: =Simulation!$E$284 | JU7: =Simulation!$E$285 | JV7: =Simulation!$E$286 | JW7: =Simulation!$E$287 | JX7: =Simulation!$E$288 | JY7: =Simulation!$E$289 | JZ7: =Simulation!$E$290 | KA7: =Simulation!$E$291 | KB7: =Simulation!$E$292 | KC7: =Simulation!$E$293 | KD7: =Simulation!$E$294 | KE7: =Simulation!$E$295 | KF7: =Simulation!$E$296 | KG7: =Simulation!$E$297 | KH7: =Simulation!$E$298 | KI7: =Simulation!$E$299 | KJ7: =Simulation!$E$300 | KK7: =Simulation!$E$301 | KL7: =Simulation!$E$302 | KM7: =Simulation!$E$303 | KN7: =Simulation!$E$304 | KO7: =Simulation!$E$305 | KP7: =Simulation!$E$306
A8: Revenue (EURk) | B8: EURk | C8: =C6*C7/1000 | D8: =D6*D7/1000 | E8: =E6*E7/1000 | F8: =F6*F7/1000 | G8: =G6*G7/1000 | H8: =H6*H7/1000 | I8: =I6*I7/1000 | J8: =J6*J7/1000 | ... KP8: =KP6*KP7/1000
A9: OPEX (EURk) | B9: EURk | C9: =-Assumptions!$E$35*(1+Assumptions!$E$36)^0/12 | D9: =-Assumptions!$E$35*(1+Assumptions!$E$36)^0/12 | E9: =-Assumptions!$E$35*(1+Assumptions!$E$36)^0/12 | F9: =-Assumptions!$E$35*(1+Assumptions!$E$36)^0/12 | G9: =-Assumptions!$E$35*(1+Assumptions!$E$36)^0/12 | H9: =-Assumptions!$E$35*(1+Assumptions!$E$36)^0/12 | I9: =-Assumptions!$E$35*(1+Assumptions!$E$36)^0/12 | J9: =-Assumptions!$E$35*(1+Assumptions!$E$36)^0/12 | ... N9: =-Assumptions!$E$35*(1+Assumptions!$E$36)^0/12 | O9: =-Assumptions!$E$35*(1+Assumptions!$E$36)^1/12 | P9: =-Assumptions!$E$35*(1+Assumptions!$E$36)^1/12 | Q9: =-Assumptions!$E$35*(1+Assumptions!$E$36)^1/12 | R9: =-Assumptions!$E$35*(1+Assumptions!$E$36)^1/12 | S9: =-Assumptions!$E$35*(1+Assumptions!$E$36)^1/12 | T9: =-Assumptions!$E$35*(1+Assumptions!$E$36)^1/12 | U9: =-Assumptions!$E$35*(1+Assumptions!$E$36)^1/12 | V9: =-Assumptions!$E$35*(1+Assumptions!$E$36)^1/12 | ... Z9: =-Assumptions!$E$35*(1+Assumptions!$E$36)^1/12 | AA9: =-Assumptions!$E$35*(1+Assumptions!$E$36)^2/12 | AB9: =-Assumptions!$E$35*(1+Assumptions!$E$36)^2/12 | AC9: =-Assumptions!$E$35*(1+Assumptions!$E$36)^2/12 | AD9: =-Assumptions!$E$35*(1+Assumptions!$E$36)^2/12 | AE9: =-Assumptions!$E$35*(1+Assumptions!$E$36)^2/12 | AF9: =-Assumptions!$E$35*(1+Assumptions!$E$36)^2/12 | AG9: =-Assumptions!$E$35*(1+Assumptions!$E$36)^2/12 | AH9: =-Assumptions!$E$35*(1+Assumptions!$E$36)^2/12 | ... AL9: =-Assumptions!$E$35*(1+Assumptions!$E$36)^2/12 | AM9: =-Assumptions!$E$35*(1+Assumptions!$E$36)^3/12 | AN9: =-Assumptions!$E$35*(1+Assumptions!$E$36)^3/12 | AO9: =-Assumptions!$E$35*(1+Assumptions!$E$36)^3/12 | AP9: =-Assumptions!$E$35*(1+Assumptions!$E$36)^3/12 | AQ9: =-Assumptions!$E$35*(1+Assumptions!$E$36)^3/12 | AR9: =-Assumptions!$E$35*(1+Assumptions!$E$36)^3/12 | AS9: =-Assumptions!$E$35*(1+Assumptions!$E$36)^3/12 | AT9: =-Assumptions!$E$35*(1+Assumptions!$E$36)^3/12 | ... AX9: =-Assumptions!$E$35*(1+Assumptions!$E$36)^3/12 | AY9: =-Assumptions!$E$35*(1+Assumptions!$E$36)^4/12 | AZ9: =-Assumptions!$E$35*(1+Assumptions!$E$36)^4/12 | BA9: =-Assumptions!$E$35*(1+Assumptions!$E$36)^4/12 | BB9: =-Assumptions!$E$35*(1+Assumptions!$E$36)^4/12 | BC9: =-Assumptions!$E$35*(1+Assumptions!$E$36)^4/12 | BD9: =-Assumptions!$E$35*(1+Assumptions!$E$36)^4/12 | BE9: =-Assumptions!$E$35*(1+Assumptions!$E$36)^4/12 | BF9: =-Assumptions!$E$35*(1+Assumptions!$E$36)^4/12 | ... BJ9: =-Assumptions!$E$35*(1+Assumptions!$E$36)^4/12 | BK9: =-Assumptions!$E$35*(1+Assumptions!$E$36)^5/12 | BL9: =-Assumptions!$E$35*(1+Assumptions!$E$36)^5/12 | BM9: =-Assumptions!$E$35*(1+Assumptions!$E$36)^5/12 | BN9: =-Assumptions!$E$35*(1+Assumptions!$E$36)^5/12 | BO9: =-Assumptions!$E$35*(1+Assumptions!$E$36)^5/12 | BP9: =-Assumptions!$E$35*(1+Assumptions!$E$36)^5/12 | BQ9: =-Assumptions!$E$35*(1+Assumptions!$E$36)^5/12 | BR9: =-Assumptions!$E$35*(1+Assumptions!$E$36)^5/12 | ... BV9: =-Assumptions!$E$35*(1+Assumptions!$E$36)^5/12 | BW9: =-Assumptions!$E$35*(1+Assumptions!$E$36)^6/12 | BX9: =-Assumptions!$E$35*(1+Assumptions!$E$36)^6/12 | BY9: =-Assumptions!$E$35*(1+Assumptions!$E$36)^6/12 | BZ9: =-Assumptions!$E$35*(1+Assumptions!$E$36)^6/12 | CA9: =-Assumptions!$E$35*(1+Assumptions!$E$36)^6/12 | CB9: =-Assumptions!$E$35*(1+Assumptions!$E$36)^6/12 | CC9: =-Assumptions!$E$35*(1+Assumptions!$E$36)^6/12 | CD9: =-Assumptions!$E$35*(1+Assumptions!$E$36)^6/12 | ... CH9: =-Assumptions!$E$35*(1+Assumptions!$E$36)^6/12 | CI9: =-Assumptions!$E$35*(1+Assumptions!$E$36)^7/12 | CJ9: =-Assumptions!$E$35*(1+Assumptions!$E$36)^7/12 | CK9: =-Assumptions!$E$35*(1+Assumptions!$E$36)^7/12 | CL9: =-Assumptions!$E$35*(1+Assumptions!$E$36)^7/12 | CM9: =-Assumptions!$E$35*(1+Assumptions!$E$36)^7/12 | CN9: =-Assumptions!$E$35*(1+Assumptions!$E$36)^7/12 | CO9: =-Assumptions!$E$35*(1+Assumptions!$E$36)^7/12 | CP9: =-Assumptions!$E$35*(1+Assumptions!$E$36)^7/12 | ... CT9: =-Assumptions!$E$35*(1+Assumptions!$E$36)^7/12 | CU9: =-Assumptions!$E$35*(1+Assumptions!$E$36)^8/12 | CV9: =-Assumptions!$E$35*(1+Assumptions!$E$36)^8/12 | CW9: =-Assumptions!$E$35*(1+Assumptions!$E$36)^8/12 | CX9: =-Assumptions!$E$35*(1+Assumptions!$E$36)^8/12 | CY9: =-Assumptions!$E$35*(1+Assumptions!$E$36)^8/12 | CZ9: =-Assumptions!$E$35*(1+Assumptions!$E$36)^8/12 | DA9: =-Assumptions!$E$35*(1+Assumptions!$E$36)^8/12 | DB9: =-Assumptions!$E$35*(1+Assumptions!$E$36)^8/12 | ... DF9: =-Assumptions!$E$35*(1+Assumptions!$E$36)^8/12 | DG9: =-Assumptions!$E$35*(1+Assumptions!$E$36)^9/12 | DH9: =-Assumptions!$E$35*(1+Assumptions!$E$36)^9/12 | DI9: =-Assumptions!$E$35*(1+Assumptions!$E$36)^9/12 | DJ9: =-Assumptions!$E$35*(1+Assumptions!$E$36)^9/12 | DK9: =-Assumptions!$E$35*(1+Assumptions!$E$36)^9/12 | DL9: =-Assumptions!$E$35*(1+Assumptions!$E$36)^9/12 | DM9: =-Assumptions!$E$35*(1+Assumptions!$E$36)^9/12 | DN9: =-Assumptions!$E$35*(1+Assumptions!$E$36)^9/12 | ... DR9: =-Assumptions!$E$35*(1+Assumptions!$E$36)^9/12 | DS9: =-Assumptions!$E$35*(1+Assumptions!$E$36)^10/12 | DT9: =-Assumptions!$E$35*(1+Assumptions!$E$36)^10/12 | DU9: =-Assumptions!$E$35*(1+Assumptions!$E$36)^10/12 | DV9: =-Assumptions!$E$35*(1+Assumptions!$E$36)^10/12 | DW9: =-Assumptions!$E$35*(1+Assumptions!$E$36)^10/12 | DX9: =-Assumptions!$E$35*(1+Assumptions!$E$36)^10/12 | DY9: =-Assumptions!$E$35*(1+Assumptions!$E$36)^10/12 | DZ9: =-Assumptions!$E$35*(1+Assumptions!$E$36)^10/12 | ... ED9: =-Assumptions!$E$35*(1+Assumptions!$E$36)^10/12 | EE9: =-Assumptions!$E$35*(1+Assumptions!$E$36)^11/12 | EF9: =-Assumptions!$E$35*(1+Assumptions!$E$36)^11/12 | EG9: =-Assumptions!$E$35*(1+Assumptions!$E$36)^11/12 | EH9: =-Assumptions!$E$35*(1+Assumptions!$E$36)^11/12 | EI9: =-Assumptions!$E$35*(1+Assumptions!$E$36)^11/12 | EJ9: =-Assumptions!$E$35*(1+Assumptions!$E$36)^11/12 | EK9: =-Assumptions!$E$35*(1+Assumptions!$E$36)^11/12 | EL9: =-Assumptions!$E$35*(1+Assumptions!$E$36)^11/12 | ... EP9: =-Assumptions!$E$35*(1+Assumptions!$E$36)^11/12 | EQ9: =-Assumptions!$E$35*(1+Assumptions!$E$36)^12/12 | ER9: =-Assumptions!$E$35*(1+Assumptions!$E$36)^12/12 | ES9: =-Assumptions!$E$35*(1+Assumptions!$E$36)^12/12 | ET9: =-Assumptions!$E$35*(1+Assumptions!$E$36)^12/12 | EU9: =-Assumptions!$E$35*(1+Assumptions!$E$36)^12/12 | EV9: =-Assumptions!$E$35*(1+Assumptions!$E$36)^12/12 | EW9: =-Assumptions!$E$35*(1+Assumptions!$E$36)^12/12 | EX9: =-Assumptions!$E$35*(1+Assumptions!$E$36)^12/12 | ... FB9: =-Assumptions!$E$35*(1+Assumptions!$E$36)^12/12 | FC9: =-Assumptions!$E$35*(1+Assumptions!$E$36)^13/12 | FD9: =-Assumptions!$E$35*(1+Assumptions!$E$36)^13/12 | FE9: =-Assumptions!$E$35*(1+Assumptions!$E$36)^13/12 | FF9: =-Assumptions!$E$35*(1+Assumptions!$E$36)^13/12 | FG9: =-Assumptions!$E$35*(1+Assumptions!$E$36)^13/12 | FH9: =-Assumptions!$E$35*(1+Assumptions!$E$36)^13/12 | FI9: =-Assumptions!$E$35*(1+Assumptions!$E$36)^13/12 | FJ9: =-Assumptions!$E$35*(1+Assumptions!$E$36)^13/12 | ... FN9: =-Assumptions!$E$35*(1+Assumptions!$E$36)^13/12 | FO9: =-Assumptions!$E$35*(1+Assumptions!$E$36)^14/12 | FP9: =-Assumptions!$E$35*(1+Assumptions!$E$36)^14/12 | FQ9: =-Assumptions!$E$35*(1+Assumptions!$E$36)^14/12 | FR9: =-Assumptions!$E$35*(1+Assumptions!$E$36)^14/12 | FS9: =-Assumptions!$E$35*(1+Assumptions!$E$36)^14/12 | FT9: =-Assumptions!$E$35*(1+Assumptions!$E$36)^14/12 | FU9: =-Assumptions!$E$35*(1+Assumptions!$E$36)^14/12 | FV9: =-Assumptions!$E$35*(1+Assumptions!$E$36)^14/12 | ... FZ9: =-Assumptions!$E$35*(1+Assumptions!$E$36)^14/12 | GA9: =-Assumptions!$E$35*(1+Assumptions!$E$36)^15/12 | GB9: =-Assumptions!$E$35*(1+Assumptions!$E$36)^15/12 | GC9: =-Assumptions!$E$35*(1+Assumptions!$E$36)^15/12 | GD9: =-Assumptions!$E$35*(1+Assumptions!$E$36)^15/12 | GE9: =-Assumptions!$E$35*(1+Assumptions!$E$36)^15/12 | GF9: =-Assumptions!$E$35*(1+Assumptions!$E$36)^15/12 | GG9: =-Assumptions!$E$35*(1+Assumptions!$E$36)^15/12 | GH9: =-Assumptions!$E$35*(1+Assumptions!$E$36)^15/12 | ... GL9: =-Assumptions!$E$35*(1+Assumptions!$E$36)^15/12 | GM9: =-Assumptions!$E$35*(1+Assumptions!$E$36)^16/12 | GN9: =-Assumptions!$E$35*(1+Assumptions!$E$36)^16/12 | GO9: =-Assumptions!$E$35*(1+Assumptions!$E$36)^16/12 | GP9: =-Assumptions!$E$35*(1+Assumptions!$E$36)^16/12 | GQ9: =-Assumptions!$E$35*(1+Assumptions!$E$36)^16/12 | GR9: =-Assumptions!$E$35*(1+Assumptions!$E$36)^16/12 | GS9: =-Assumptions!$E$35*(1+Assumptions!$E$36)^16/12 | GT9: =-Assumptions!$E$35*(1+Assumptions!$E$36)^16/12 | ... GX9: =-Assumptions!$E$35*(1+Assumptions!$E$36)^16/12 | GY9: =-Assumptions!$E$35*(1+Assumptions!$E$36)^17/12 | GZ9: =-Assumptions!$E$35*(1+Assumptions!$E$36)^17/12 | HA9: =-Assumptions!$E$35*(1+Assumptions!$E$36)^17/12 | HB9: =-Assumptions!$E$35*(1+Assumptions!$E$36)^17/12 | HC9: =-Assumptions!$E$35*(1+Assumptions!$E$36)^17/12 | HD9: =-Assumptions!$E$35*(1+Assumptions!$E$36)^17/12 | HE9: =-Assumptions!$E$35*(1+Assumptions!$E$36)^17/12 | HF9: =-Assumptions!$E$35*(1+Assumptions!$E$36)^17/12 | ... HJ9: =-Assumptions!$E$35*(1+Assumptions!$E$36)^17/12 | HK9: =-Assumptions!$E$35*(1+Assumptions!$E$36)^18/12 | HL9: =-Assumptions!$E$35*(1+Assumptions!$E$36)^18/12 | HM9: =-Assumptions!$E$35*(1+Assumptions!$E$36)^18/12 | HN9: =-Assumptions!$E$35*(1+Assumptions!$E$36)^18/12 | HO9: =-Assumptions!$E$35*(1+Assumptions!$E$36)^18/12 | HP9: =-Assumptions!$E$35*(1+Assumptions!$E$36)^18/12 | HQ9: =-Assumptions!$E$35*(1+Assumptions!$E$36)^18/12 | HR9: =-Assumptions!$E$35*(1+Assumptions!$E$36)^18/12 | ... HV9: =-Assumptions!$E$35*(1+Assumptions!$E$36)^18/12 | HW9: =-Assumptions!$E$35*(1+Assumptions!$E$36)^19/12 | HX9: =-Assumptions!$E$35*(1+Assumptions!$E$36)^19/12 | HY9: =-Assumptions!$E$35*(1+Assumptions!$E$36)^19/12 | HZ9: =-Assumptions!$E$35*(1+Assumptions!$E$36)^19/12 | IA9: =-Assumptions!$E$35*(1+Assumptions!$E$36)^19/12 | IB9: =-Assumptions!$E$35*(1+Assumptions!$E$36)^19/12 | IC9: =-Assumptions!$E$35*(1+Assumptions!$E$36)^19/12 | ID9: =-Assumptions!$E$35*(1+Assumptions!$E$36)^19/12 | ... IH9: =-Assumptions!$E$35*(1+Assumptions!$E$36)^19/12 | II9: =-Assumptions!$E$35*(1+Assumptions!$E$36)^20/12 | IJ9: =-Assumptions!$E$35*(1+Assumptions!$E$36)^20/12 | IK9: =-Assumptions!$E$35*(1+Assumptions!$E$36)^20/12 | IL9: =-Assumptions!$E$35*(1+Assumptions!$E$36)^20/12 | IM9: =-Assumptions!$E$35*(1+Assumptions!$E$36)^20/12 | IN9: =-Assumptions!$E$35*(1+Assumptions!$E$36)^20/12 | IO9: =-Assumptions!$E$35*(1+Assumptions!$E$36)^20/12 | IP9: =-Assumptions!$E$35*(1+Assumptions!$E$36)^20/12 | ... IT9: =-Assumptions!$E$35*(1+Assumptions!$E$36)^20/12 | IU9: =-Assumptions!$E$35*(1+Assumptions!$E$36)^21/12 | IV9: =-Assumptions!$E$35*(1+Assumptions!$E$36)^21/12 | IW9: =-Assumptions!$E$35*(1+Assumptions!$E$36)^21/12 | IX9: =-Assumptions!$E$35*(1+Assumptions!$E$36)^21/12 | IY9: =-Assumptions!$E$35*(1+Assumptions!$E$36)^21/12 | IZ9: =-Assumptions!$E$35*(1+Assumptions!$E$36)^21/12 | JA9: =-Assumptions!$E$35*(1+Assumptions!$E$36)^21/12 | JB9: =-Assumptions!$E$35*(1+Assumptions!$E$36)^21/12 | ... JF9: =-Assumptions!$E$35*(1+Assumptions!$E$36)^21/12 | JG9: =-Assumptions!$E$35*(1+Assumptions!$E$36)^22/12 | JH9: =-Assumptions!$E$35*(1+Assumptions!$E$36)^22/12 | JI9: =-Assumptions!$E$35*(1+Assumptions!$E$36)^22/12 | JJ9: =-Assumptions!$E$35*(1+Assumptions!$E$36)^22/12 | JK9: =-Assumptions!$E$35*(1+Assumptions!$E$36)^22/12 | JL9: =-Assumptions!$E$35*(1+Assumptions!$E$36)^22/12 | JM9: =-Assumptions!$E$35*(1+Assumptions!$E$36)^22/12 | JN9: =-Assumptions!$E$35*(1+Assumptions!$E$36)^22/12 | ... JR9: =-Assumptions!$E$35*(1+Assumptions!$E$36)^22/12 | JS9: =-Assumptions!$E$35*(1+Assumptions!$E$36)^23/12 | JT9: =-Assumptions!$E$35*(1+Assumptions!$E$36)^23/12 | JU9: =-Assumptions!$E$35*(1+Assumptions!$E$36)^23/12 | JV9: =-Assumptions!$E$35*(1+Assumptions!$E$36)^23/12 | JW9: =-Assumptions!$E$35*(1+Assumptions!$E$36)^23/12 | JX9: =-Assumptions!$E$35*(1+Assumptions!$E$36)^23/12 | JY9: =-Assumptions!$E$35*(1+Assumptions!$E$36)^23/12 | JZ9: =-Assumptions!$E$35*(1+Assumptions!$E$36)^23/12 | ... KD9: =-Assumptions!$E$35*(1+Assumptions!$E$36)^23/12 | KE9: =-Assumptions!$E$35*(1+Assumptions!$E$36)^24/12 | KF9: =-Assumptions!$E$35*(1+Assumptions!$E$36)^24/12 | KG9: =-Assumptions!$E$35*(1+Assumptions!$E$36)^24/12 | KH9: =-Assumptions!$E$35*(1+Assumptions!$E$36)^24/12 | KI9: =-Assumptions!$E$35*(1+Assumptions!$E$36)^24/12 | KJ9: =-Assumptions!$E$35*(1+Assumptions!$E$36)^24/12 | KK9: =-Assumptions!$E$35*(1+Assumptions!$E$36)^24/12 | KL9: =-Assumptions!$E$35*(1+Assumptions!$E$36)^24/12 | ... KP9: =-Assumptions!$E$35*(1+Assumptions!$E$36)^24/12
A10: EBITDA (EURk) | B10: EURk | C10: =C8+C9 | D10: =D8+D9 | E10: =E8+E9 | F10: =F8+F9 | G10: =G8+G9 | H10: =H8+H9 | I10: =I8+I9 | J10: =J8+J9 | ... KP10: =KP8+KP9
